Workbook

Sheet usersPost
A1: userInfoUid | B1: firstName | C1: surname | D1: email | E1: phoneNumber | F1: username | G1: password | H1: userRoles | I1: userGroups | J1: organisationUnits | K1: userinfi_id | L1: orgid | M1: dataViewOrganisationUnits | N1: teiSearchOrganisationUnits | O1: insert into userdatavieworgunits ( userinfoid, organisationunitid ) values | P1: insert into usermembership ( organisationunitid, userinfoid ) values | Q1: insert into userteisearchorgunits ( userinfoid, organisationunitid ) values
A2: pmYRU1YQqKP | B2: Jesan | C2: Nava | F2: jesan_nava | G2: Pmnp@2025 | H2: RgsiAXF6U8e,EWJtSoaytdF | I2: EcTqBndpJRF,X76IjKG0XFz | J2: DcGhhRsspFX | K2: =VLOOKUP(A2,Sheet2!$A$2:$B$621,2,FALSE) -> 662467 | L2: =VLOOKUP(J2,Sheet1!$A$2:$D$6211,2,FALSE) -> 71 | M2: DcGhhRsspFX | N2: DcGhhRsspFX | O2: ="("&K2&","&L2&")," -> (662467,71), | P2: ="("&L2&","&K2&")," -> (71,662467), | Q2: ="("&K2&","&L2&")," -> (662467,71), | R2: =K2&"," -> 662467,
A3: F7vO0P4BC45 | B3: Mark | C3: Vinarao | F3: mark_vinarao | G3: Pmnp@2025 | H3: RgsiAXF6U8e,EWJtSoaytdF | I3: EcTqBndpJRF,X76IjKG0XFz | J3: spXTh9hs5dz | K3: =VLOOKUP(A3,Sheet2!$A$2:$B$621,2,FALSE) -> 662468 | L3: =VLOOKUP(J3,Sheet1!$A$2:$D$6211,2,FALSE) -> 81 | M3: spXTh9hs5dz | N3: spXTh9hs5dz | O3: ="("&K3&","&L3&")," -> (662468,81), | P3: ="("&L3&","&K3&")," -> (81,662468), | Q3: ="("&K3&","&L3&")," -> (662468,81), | R3: =K3&"," -> 662468,
A4: SfLrNOUCXC4 | B4: Claudine | C4: Tomas | F4: claudine_tomas | G4: Pmnp@2025 | H4: RgsiAXF6U8e,EWJtSoaytdF | I4: EcTqBndpJRF,X76IjKG0XFz | J4: spXTh9hs5dz | K4: =VLOOKUP(A4,Sheet2!$A$2:$B$621,2,FALSE) -> 662469 | L4: =VLOOKUP(J4,Sheet1!$A$2:$D$6211,2,FALSE) -> 81 | M4: spXTh9hs5dz | N4: spXTh9hs5dz | O4: ="("&K4&","&L4&")," -> (662469,81), | P4: ="("&L4&","&K4&")," -> (81,662469), | Q4: ="("&K4&","&L4&")," -> (662469,81), | R4: =K4&"," -> 662469,
A5: IjJm4geDA8Z | B5: Angelita | C5: Pasos | F5: angelita_pasos | G5: Pmnp@2025 | H5: RgsiAXF6U8e,EWJtSoaytdF | I5: EcTqBndpJRF,X76IjKG0XFz | J5: spXTh9hs5dz | K5: =VLOOKUP(A5,Sheet2!$A$2:$B$621,2,FALSE) -> 662470 | L5: =VLOOKUP(J5,Sheet1!$A$2:$D$6211,2,FALSE) -> 81 | M5: spXTh9hs5dz | N5: spXTh9hs5dz | O5: ="("&K5&","&L5&")," -> (662470,81), | P5: ="("&L5&","&K5&")," -> (81,662470), | Q5: ="("&K5&","&L5&")," -> (662470,81), | R5: =K5&"," -> 662470,
A6: HIDVkl6BIjG | B6: Nova | C6: Ballesteros | F6: nova_ballesteros | G6: Pmnp@2025 | H6: RgsiAXF6U8e,EWJtSoaytdF | I6: EcTqBndpJRF,X76IjKG0XFz | J6: spXTh9hs5dz | K6: =VLOOKUP(A6,Sheet2!$A$2:$B$621,2,FALSE) -> 662471 | L6: =VLOOKUP(J6,Sheet1!$A$2:$D$6211,2,FALSE) -> 81 | M6: spXTh9hs5dz | N6: spXTh9hs5dz | O6: ="("&K6&","&L6&")," -> (662471,81), | P6: ="("&L6&","&K6&")," -> (81,662471), | Q6: ="("&K6&","&L6&")," -> (662471,81), | R6: =K6&"," -> 662471,
A7: TrAcVcz5hUf | B7: Trisha | C7: Boado | F7: trisha_boado | G7: Pmnp@2025 | H7: RgsiAXF6U8e,EWJtSoaytdF | I7: EcTqBndpJRF,X76IjKG0XFz | J7: spXTh9hs5dz | K7: =VLOOKUP(A7,Sheet2!$A$2:$B$621,2,FALSE) -> 662472 | L7: =VLOOKUP(J7,Sheet1!$A$2:$D$6211,2,FALSE) -> 81 | M7: spXTh9hs5dz | N7: spXTh9hs5dz | O7: ="("&K7&","&L7&")," -> (662472,81), | P7: ="("&L7&","&K7&")," -> (81,662472), | Q7: ="("&K7&","&L7&")," -> (662472,81), | R7: =K7&"," -> 662472,
A8: zm3gO7qqadH | B8: Katherine | C8: Andujare-Paran | F8: katherine_andujare-paran | G8: Pmnp@2025 | H8: RgsiAXF6U8e,EWJtSoaytdF | I8: EcTqBndpJRF,X76IjKG0XFz | J8: g6OKJ39e5pV | K8: =VLOOKUP(A8,Sheet2!$A$2:$B$621,2,FALSE) -> 662473 | L8: =VLOOKUP(J8,Sheet1!$A$2:$D$6211,2,FALSE) -> 79 | M8: g6OKJ39e5pV | N8: g6OKJ39e5pV | O8: ="("&K8&","&L8&")," -> (662473,79), | P8: ="("&L8&","&K8&")," -> (79,662473), | Q8: ="("&K8&","&L8&")," -> (662473,79), | R8: =K8&"," -> 662473,
A9: ukyC0KuoxYS | B9: Mark | C9: Reblora | F9: mark_reblora | G9: Pmnp@2025 | H9: RgsiAXF6U8e,EWJtSoaytdF | I9: EcTqBndpJRF,X76IjKG0XFz | J9: g6OKJ39e5pV | K9: =VLOOKUP(A9,Sheet2!$A$2:$B$621,2,FALSE) -> 662474 | L9: =VLOOKUP(J9,Sheet1!$A$2:$D$6211,2,FALSE) -> 79 | M9: g6OKJ39e5pV | N9: g6OKJ39e5pV | O9: ="("&K9&","&L9&")," -> (662474,79), | P9: ="("&L9&","&K9&")," -> (79,662474), | Q9: ="("&K9&","&L9&")," -> (662474,79), | R9: =K9&"," -> 662474,
A10: ljTifdDqglN | B10: Jhonnadelle | C10: Castillo | F10: jhonnadelle_castillo | G10: Pmnp@2025 | H10: RgsiAXF6U8e,EWJtSoaytdF | I10: EcTqBndpJRF,X76IjKG0XFz | J10: g6OKJ39e5pV | K10: =VLOOKUP(A10,Sheet2!$A$2:$B$621,2,FALSE) -> 662475 | L10: =VLOOKUP(J10,Sheet1!$A$2:$D$6211,2,FALSE) -> 79 | M10: g6OKJ39e5pV | N10: g6OKJ39e5pV | O10: ="("&K10&","&L10&")," -> (662475,79), | P10: ="("&L10&","&K10&")," -> (79,662475), | Q10: ="("&K10&","&L10&")," -> (662475,79), | R10: =K10&"," -> 662475,
A11: BGq2WYLQkgC | B11: Mark | C11: Lorenzo | F11: mark_lorenzo | G11: Pmnp@2025 | H11: RgsiAXF6U8e,EWJtSoaytdF | I11: EcTqBndpJRF,X76IjKG0XFz | J11: P2cGU4ONQ4p | K11: =VLOOKUP(A11,Sheet2!$A$2:$B$621,2,FALSE) -> 662476 | L11: =VLOOKUP(J11,Sheet1!$A$2:$D$6211,2,FALSE) -> 80 | M11: P2cGU4ONQ4p | N11: P2cGU4ONQ4p | O11: ="("&K11&","&L11&")," -> (662476,80), | P11: ="("&L11&","&K11&")," -> (80,662476), | Q11: ="("&K11&","&L11&")," -> (662476,80), | R11: =K11&"," -> 662476,
A12: NczxzoluCxt | B12: Azalea | C12: Malabana | F12: azalea_malabana | G12: Pmnp@2025 | H12: RgsiAXF6U8e,EWJtSoaytdF | I12: EcTqBndpJRF,X76IjKG0XFz | J12: P2cGU4ONQ4p | K12: =VLOOKUP(A12,Sheet2!$A$2:$B$621,2,FALSE) -> 662477 | L12: =VLOOKUP(J12,Sheet1!$A$2:$D$6211,2,FALSE) -> 80 | M12: P2cGU4ONQ4p | N12: P2cGU4ONQ4p | O12: ="("&K12&","&L12&")," -> (662477,80), | P12: ="("&L12&","&K12&")," -> (80,662477), | Q12: ="("&K12&","&L12&")," -> (662477,80), | R12: =K12&"," -> 662477,
A13: AYhUt940zbs | B13: Johnna | C13: Valencia | F13: johnna_valencia | G13: Pmnp@2025 | H13: RgsiAXF6U8e,EWJtSoaytdF | I13: EcTqBndpJRF,X76IjKG0XFz | J13: P2cGU4ONQ4p | K13: =VLOOKUP(A13,Sheet2!$A$2:$B$621,2,FALSE) -> 662478 | L13: =VLOOKUP(J13,Sheet1!$A$2:$D$6211,2,FALSE) -> 80 | M13: P2cGU4ONQ4p | N13: P2cGU4ONQ4p | O13: ="("&K13&","&L13&")," -> (662478,80), | P13: ="("&L13&","&K13&")," -> (80,662478), | Q13: ="("&K13&","&L13&")," -> (662478,80), | R13: =K13&"," -> 662478,
... A119: oScGhjDhxGM | B119: Data | C119: Collector 59 | F119: westvisayas_dc15 | G119: Pmnp@2025 | H119: MUNroCPg9tl | I119: VfVrBMOl8tH | J119: i9LhFBVDKcy | K119: =VLOOKUP(A119,Sheet2!$A$2:$B$621,2,FALSE) -> 662583 | L119: =VLOOKUP(J119,Sheet1!$A$2:$D$6211,2,FALSE) -> 619485 | M119: i9LhFBVDKcy | N119: i9LhFBVDKcy | O119: ="("&K119&","&L119&")," -> (662583,619485), | P119: ="("&L119&","&K119&")," -> (619485,662583), | Q119: ="("&K119&","&L119&")," -> (662583,619485), | R119: =K119&"," -> 662583,

Sheet Sheet2
A1: uid | B1: id
A2: i7ijaOvdKPf | B2: 600562
A3: JVTMYSXPulG | B3: 604002
A4: PuZ6bBhPNL0 | B4: 7074
A5: Q296rDXLMR8 | B5: 604045
A6: E1lIhyG7Qqa | B6: 602094
A7: NczxzoluCxt | B7: 662477
A8: pFXd9f5qJiU | B8: 604056
A9: zZvRvsOWaI7 | B9: 602095
A10: nTO0xU319yi | B10: 602101
A11: SrVktgaucM5 | B11: 603998
A12: zFgBjFzwHd6 | B12: 7075
A13: ySMg7J0gtnb | B13: 7072
... A621: TIvRi6hbq9E | B621: 662506

Sheet Sheet1
A1: uid | B1: id | C1: code
A2: IqpQHGyORV3 | B2: 610231 | C2: 0502000000
A3: ZQBdFVxYVGl | B3: 605979 | C3: 0802601000
A4: f2mqNxmuZfM | B4: 605980 | C4: 0802603000
A5: p1gPHzj79rV | B5: 605981 | C5: 0802605000
A6: AnZlHja1aox | B6: 605982 | C6: 0802607000
A7: UkGUK6T2EM0 | B7: 605983 | C7: 0802608000
A8: embHEGR6U3M | B8: 605984 | C8: 0802610000
A9: sIhE3ucppGJ | B9: 601393 | C9: 1705903002
A10: bPH52dgLnBc | B10: 601394 | C10: 1705903003
A11: J3nklsmu0TB | B11: 601065 | C11: 1705900000
A12: rO1qaPLl9eq | B12: 605985 | C12: 0802611000
A13: mzO4rLF8rRA | B13: 605986 | C13: 0802612000
... A38: v70IgUHgZYD | B38: 89 | C38: 1600000000
A39: DcGhhRsspFX | B39: 71
A40: mut1oGsi6Hn | B40: 606000 | C40: 0803721000
A41: XZZKrhU1Q9a | B41: 606001 | C41: 0803722000
A42: OX7LmrF8WJa | B42: 606002 | C42: 0803724000
A43: QYO0nBwXHdt | B43: 606003 | C43: 0803728000
A44: uVdJR9WSgPj | B44: 606004 | C44: 0803729000
A45: vnwXB8puJCu | B45: 606005 | C45: 0803730000
A46: NmiJ9KH1DZe | B46: 606006 | C46: 0803731000
A47: WeNO3ACQ1pC | B47: 606007 | C47: 0803734000
A48: vNRXkwAwhSm | B48: 606008 | C48: 0803735000
A49: i4JTxRGScxC | B49: 606009 | C49: 0803739000
A50: sxkSlsiQ9BA | B50: 606010 | C50: 0803740000
A51: d4dqa4QThq3 | B51: 606011 | C51: 0803741000
... A375: pGEQ7ZyLQxY | B375: 606224 | C375: 0802614003
A376: TCtgHM2wMwz | B376: 605658
A377: owPO2pYw6K8 | B377: 606225 | C377: 0802614005
A378: B5JLEiaRcBD | B378: 606226 | C378: 0802614006
A379: Meuju4PkOzG | B379: 606227 | C379: 0802614007
A380: H8qTuqtmj1b | B380: 606228 | C380: 0802614008
A381: MrM8UttYYht | B381: 606229 | C381: 0802614009
A382: tMrtA0cgwyV | B382: 606230 | C382: 0802614010
A383: FgUs8ioOl0u | B383: 606231 | C383: 0802614011
A384: o99t6UpCfBW | B384: 606232 | C384: 0802614012
A385: qxnQzhvJTQD | B385: 606233 | C385: 0802614013
A386: JSVp2Jn4Goj | B386: 606234 | C386: 0802614014
A387: SLCVdUwvUcm | B387: 606235 | C387: 0802615002
...
